Workbook

Sheet Instructions
A1: Project Tracker Instructions
A2: Use Employee_Master for employees and Task_Tracker for all task entry. Monthly tabs show due tasks by month and auto-display carry-forward open tasks from earlier months.
A3: Workflow
A4: 1. Add or update employees in Employee_Master.
A5: 2. Add or edit tasks only in Task_Tracker.
A6: 3. Due Date controls the month-wise reporting tabs.
A7: 4. Any task not marked Completed or Cancelled before a later month will appear in Carry Forward for that month.
A8: 5. Use Monthly_Report_Summary for month-wise totals and employee report tabs for individual performance.
A9: Editable areas
A10: Unlocked input cells are available in Employee_Master, Task_Tracker, and B4/B5 on the general Employee_Report.
A11: Protection password
A12: TaskLock2026!
A13: Reporting logic
A14: Tasks Due This Month = tasks with Due Date inside the month. | B14: User input
A15: Completed = tasks in that month bucket with Status = Completed. | B15: Auto-calculated / locked
A16: Carry Forward = tasks with Due Date before the month start that are still not Completed/Cancelled. | B16: Linked from another sheet
A17: Hours are summarized from the task-level Actual Hours field. | B17: Overdue or attention needed
A18: Dark blue bars | B18: Section headers / KPI blocks
A20: Latest updates
A21: - Employee names now come from Employee_Master: Pammi Gaur and Pankaj Vairagade.
A22: - Use Task_Tracker column AA for Source. Manager, report status, and linked step IDs are auto-filled.
A23: - Use Task_Steps Parent Task ID dropdown to map each step back to the Task_Tracker.
A24: - Employee and manager reports now pull directly from Task_Tracker and Task_Steps.

Sheet Dashboard
A1: Dashboard
A2: Dashboard summary of project delivery. Use Monthly_Report_Summary and month tabs for month-wise reporting.
A4: Selected Month | B4: All
A6: Total Tasks | D6: Open Tasks | G6: Completed | J6: Overdue
A7: =IF($B$4="All",COUNTIF(Task_Tracker!$D$5:$D$1004,"<>"),COUNTIFS(Task_Tracker!$S$5:$S$1004,$B$4,Task_Tracker!$D$5:$D$1004,"<>")) | D7: =IF($B$4="All",COUNTIFS(Task_Tracker!$D$5:$D$1004,"<>",Task_Tracker!$I$5:$I$1004,"<>Completed",Task_Tracker!$I$5:$I$1004,"<>Cancelled"),COUNTIFS(Task_Tracker!$S$5:$S$1004,$B$4,Task_Tracker!$I$5:$I$1004,"<>Completed",Task_Tracker!$I$5:$I$1004,"<>Cancelled")) | G7: =IF($B$4="All",COUNTIFS(Task_Tracker!$I$5:$I$1004,"Completed"),COUNTIFS(Task_Tracker!$S$5:$S$1004,$B$4,Task_Tracker!$I$5:$I$1004,"Completed")) | J7: =IF($B$4="All",COUNTIFS(Task_Tracker!$R$5:$R$1004,"Overdue"),COUNTIFS(Task_Tracker!$S$5:$S$1004,$B$4,Task_Tracker!$R$5:$R$1004,"Overdue"))
A9: Estimated Hours | D9: Actual Hours | G9: Hours Variance | J9: Completion Rate
A10: =IF($B$4="All",SUM(Task_Tracker!$N$5:$N$1004),SUMIFS(Task_Tracker!$N$5:$N$1004,Task_Tracker!$S$5:$S$1004,$B$4)) | D10: =IF($B$4="All",SUM(Task_Tracker!$O$5:$O$1004),SUMIFS(Task_Tracker!$O$5:$O$1004,Task_Tracker!$S$5:$S$1004,$B$4)) | G10: =IF(OR(A10="",D10=""),"",D10-A10) | J10: =IFERROR(G7/A7,"")
A13: 12-month trend | F13: Status summary | I13: Employee workload snapshot
A14: Month | B14: Tasks Due | C14: Completed | D14: Actual Hours | F14: Status | G14: Count | I14: Employee | J14: Tasks | K14: Actual Hrs | L14: Overdue
A15: 2026-04 | B15: =COUNTIFS(Task_Tracker!$S$5:$S$1004,$A15,Task_Tracker!$A$5:$A$1004,"<>") | C15: =COUNTIFS(Task_Tracker!$S$5:$S$1004,$A15,Task_Tracker!$I$5:$I$1004,"Completed") | D15: =SUMIFS(Task_Tracker!$O$5:$O$1004,Task_Tracker!$S$5:$S$1004,$A15) | F15: Not Started | G15: =IF($B$4="All",COUNTIFS(Task_Tracker!$I$5:$I$1004,$F15),COUNTIFS(Task_Tracker!$S$5:$S$1004,$B$4,Task_Tracker!$I$5:$I$1004,$F15)) | I15: =Employee_Summary!B5 | J15: =IF($I15="","",IF($B$4="All",COUNTIF(Task_Tracker!$F$5:$F$1004,$I15),COUNTIFS(Task_Tracker!$F$5:$F$1004,$I15,Task_Tracker!$S$5:$S$1004,$B$4))) | K15: =IF($I15="","",IF($B$4="All",SUMIF(Task_Tracker!$F$5:$F$1004,$I15,Task_Tracker!$O$5:$O$1004),SUMIFS(Task_Tracker!$O$5:$O$1004,Task_Tracker!$F$5:$F$1004,$I15,Task_Tracker!$S$5:$S$1004,$B$4))) | L15: =IF($I15="","",IF($B$4="All",COUNTIFS(Task_Tracker!$F$5:$F$1004,$I15,Task_Tracker!$R$5:$R$1004,"Overdue"),COUNTIFS(Task_Tracker!$F$5:$F$1004,$I15,Task_Tracker!$R$5:$R$1004,"Overdue",Task_Tracker!$S$5:$S$1004,$B$4)))
A16: 2026-05 | B16: =COUNTIFS(Task_Tracker!$S$5:$S$1004,$A16,Task_Tracker!$A$5:$A$1004,"<>") | C16: =COUNTIFS(Task_Tracker!$S$5:$S$1004,$A16,Task_Tracker!$I$5:$I$1004,"Completed") | D16: =SUMIFS(Task_Tracker!$O$5:$O$1004,Task_Tracker!$S$5:$S$1004,$A16) | F16: In Progress | G16: =IF($B$4="All",COUNTIFS(Task_Tracker!$I$5:$I$1004,$F16),COUNTIFS(Task_Tracker!$S$5:$S$1004,$B$4,Task_Tracker!$I$5:$I$1004,$F16)) | I16: =Employee_Summary!B6 | J16: =IF($I16="","",IF($B$4="All",COUNTIF(Task_Tracker!$F$5:$F$1004,$I16),COUNTIFS(Task_Tracker!$F$5:$F$1004,$I16,Task_Tracker!$S$5:$S$1004,$B$4))) | K16: =IF($I16="","",IF($B$4="All",SUMIF(Task_Tracker!$F$5:$F$1004,$I16,Task_Tracker!$O$5:$O$1004),SUMIFS(Task_Tracker!$O$5:$O$1004,Task_Tracker!$F$5:$F$1004,$I16,Task_Tracker!$S$5:$S$1004,$B$4))) | L16: =IF($I16="","",IF($B$4="All",COUNTIFS(Task_Tracker!$F$5:$F$1004,$I16,Task_Tracker!$R$5:$R$1004,"Overdue"),COUNTIFS(Task_Tracker!$F$5:$F$1004,$I16,Task_Tracker!$R$5:$R$1004,"Overdue",Task_Tracker!$S$5:$S$1004,$B$4)))
A17: 2026-06 | B17: =COUNTIFS(Task_Tracker!$S$5:$S$1004,$A17,Task_Tracker!$A$5:$A$1004,"<>") | C17: =COUNTIFS(Task_Tracker!$S$5:$S$1004,$A17,Task_Tracker!$I$5:$I$1004,"Completed") | D17: =SUMIFS(Task_Tracker!$O$5:$O$1004,Task_Tracker!$S$5:$S$1004,$A17) | F17: Review | G17: =IF($B$4="All",COUNTIFS(Task_Tracker!$I$5:$I$1004,$F17),COUNTIFS(Task_Tracker!$S$5:$S$1004,$B$4,Task_Tracker!$I$5:$I$1004,$F17)) | I17: =Employee_Summary!B7 | J17: =IF($I17="","",IF($B$4="All",COUNTIF(Task_Tracker!$F$5:$F$1004,$I17),COUNTIFS(Task_Tracker!$F$5:$F$1004,$I17,Task_Tracker!$S$5:$S$1004,$B$4))) | K17: =IF($I17="","",IF($B$4="All",SUMIF(Task_Tracker!$F$5:$F$1004,$I17,Task_Tracker!$O$5:$O$1004),SUMIFS(Task_Tracker!$O$5:$O$1004,Task_Tracker!$F$5:$F$1004,$I17,Task_Tracker!$S$5:$S$1004,$B$4))) | L17: =IF($I17="","",IF($B$4="All",COUNTIFS(Task_Tracker!$F$5:$F$1004,$I17,Task_Tracker!$R$5:$R$1004,"Overdue"),COUNTIFS(Task_Tracker!$F$5:$F$1004,$I17,Task_Tracker!$R$5:$R$1004,"Overdue",Task_Tracker!$S$5:$S$1004,$B$4)))
A18: 2026-07 | B18: =COUNTIFS(Task_Tracker!$S$5:$S$1004,$A18,Task_Tracker!$A$5:$A$1004,"<>") | C18: =COUNTIFS(Task_Tracker!$S$5:$S$1004,$A18,Task_Tracker!$I$5:$I$1004,"Completed") | D18: =SUMIFS(Task_Tracker!$O$5:$O$1004,Task_Tracker!$S$5:$S$1004,$A18) | F18: On Hold | G18: =IF($B$4="All",COUNTIFS(Task_Tracker!$I$5:$I$1004,$F18),COUNTIFS(Task_Tracker!$S$5:$S$1004,$B$4,Task_Tracker!$I$5:$I$1004,$F18)) | I18: =Employee_Summary!B8 | J18: =IF($I18="","",IF($B$4="All",COUNTIF(Task_Tracker!$F$5:$F$1004,$I18),COUNTIFS(Task_Tracker!$F$5:$F$1004,$I18,Task_Tracker!$S$5:$S$1004,$B$4))) | K18: =IF($I18="","",IF($B$4="All",SUMIF(Task_Tracker!$F$5:$F$1004,$I18,Task_Tracker!$O$5:$O$1004),SUMIFS(Task_Tracker!$O$5:$O$1004,Task_Tracker!$F$5:$F$1004,$I18,Task_Tracker!$S$5:$S$1004,$B$4))) | L18: =IF($I18="","",IF($B$4="All",COUNTIFS(Task_Tracker!$F$5:$F$1004,$I18,Task_Tracker!$R$5:$R$1004,"Overdue"),COUNTIFS(Task_Tracker!$F$5:$F$1004,$I18,Task_Tracker!$R$5:$R$1004,"Overdue",Task_Tracker!$S$5:$S$1004,$B$4)))
A19: 2026-08 | B19: =COUNTIFS(Task_Tracker!$S$5:$S$1004,$A19,Task_Tracker!$A$5:$A$1004,"<>") | C19: =COUNTIFS(Task_Tracker!$S$5:$S$1004,$A19,Task_Tracker!$I$5:$I$1004,"Completed") | D19: =SUMIFS(Task_Tracker!$O$5:$O$1004,Task_Tracker!$S$5:$S$1004,$A19) | F19: Blocked | G19: =IF($B$4="All",COUNTIFS(Task_Tracker!$I$5:$I$1004,$F19),COUNTIFS(Task_Tracker!$S$5:$S$1004,$B$4,Task_Tracker!$I$5:$I$1004,$F19)) | I19: =Employee_Summary!B9 | J19: =IF($I19="","",IF($B$4="All",COUNTIF(Task_Tracker!$F$5:$F$1004,$I19),COUNTIFS(Task_Tracker!$F$5:$F$1004,$I19,Task_Tracker!$S$5:$S$1004,$B$4))) | K19: =IF($I19="","",IF($B$4="All",SUMIF(Task_Tracker!$F$5:$F$1004,$I19,Task_Tracker!$O$5:$O$1004),SUMIFS(Task_Tracker!$O$5:$O$1004,Task_Tracker!$F$5:$F$1004,$I19,Task_Tracker!$S$5:$S$1004,$B$4))) | L19: =IF($I19="","",IF($B$4="All",COUNTIFS(Task_Tracker!$F$5:$F$1004,$I19,Task_Tracker!$R$5:$R$1004,"Overdue"),COUNTIFS(Task_Tracker!$F$5:$F$1004,$I19,Task_Tracker!$R$5:$R$1004,"Overdue",Task_Tracker!$S$5:$S$1004,$B$4)))
A20: 2026-09 | B20: =COUNTIFS(Task_Tracker!$S$5:$S$1004,$A20,Task_Tracker!$A$5:$A$1004,"<>") | C20: =COUNTIFS(Task_Tracker!$S$5:$S$1004,$A20,Task_Tracker!$I$5:$I$1004,"Completed") | D20: =SUMIFS(Task_Tracker!$O$5:$O$1004,Task_Tracker!$S$5:$S$1004,$A20) | F20: Completed | G20: =IF($B$4="All",COUNTIFS(Task_Tracker!$I$5:$I$1004,$F20),COUNTIFS(Task_Tracker!$S$5:$S$1004,$B$4,Task_Tracker!$I$5:$I$1004,$F20)) | I20: =Employee_Summary!B10 | J20: =IF($I20="","",IF($B$4="All",COUNTIF(Task_Tracker!$F$5:$F$1004,$I20),COUNTIFS(Task_Tracker!$F$5:$F$1004,$I20,Task_Tracker!$S$5:$S$1004,$B$4))) | K20: =IF($I20="","",IF($B$4="All",SUMIF(Task_Tracker!$F$5:$F$1004,$I20,Task_Tracker!$O$5:$O$1004),SUMIFS(Task_Tracker!$O$5:$O$1004,Task_Tracker!$F$5:$F$1004,$I20,Task_Tracker!$S$5:$S$1004,$B$4))) | L20: =IF($I20="","",IF($B$4="All",COUNTIFS(Task_Tracker!$F$5:$F$1004,$I20,Task_Tracker!$R$5:$R$1004,"Overdue"),COUNTIFS(Task_Tracker!$F$5:$F$1004,$I20,Task_Tracker!$R$5:$R$1004,"Overdue",Task_Tracker!$S$5:$S$1004,$B$4)))
A21: 2026-10 | B21: =COUNTIFS(Task_Tracker!$S$5:$S$1004,$A21,Task_Tracker!$A$5:$A$1004,"<>") | C21: =COUNTIFS(Task_Tracker!$S$5:$S$1004,$A21,Task_Tracker!$I$5:$I$1004,"Completed") | D21: =SUMIFS(Task_Tracker!$O$5:$O$1004,Task_Tracker!$S$5:$S$1004,$A21) | F21: Cancelled | G21: =IF($B$4="All",COUNTIFS(Task_Tracker!$I$5:$I$1004,$F21),COUNTIFS(Task_Tracker!$S$5:$S$1004,$B$4,Task_Tracker!$I$5:$I$1004,$F21)) | I21: =Employee_Summary!B11 | J21: =IF($I21="","",IF($B$4="All",COUNTIF(Task_Tracker!$F$5:$F$1004,$I21),COUNTIFS(Task_Tracker!$F$5:$F$1004,$I21,Task_Tracker!$S$5:$S$1004,$B$4))) | K21: =IF($I21="","",IF($B$4="All",SUMIF(Task_Tracker!$F$5:$F$1004,$I21,Task_Tracker!$O$5:$O$1004),SUMIFS(Task_Tracker!$O$5:$O$1004,Task_Tracker!$F$5:$F$1004,$I21,Task_Tracker!$S$5:$S$1004,$B$4))) | L21: =IF($I21="","",IF($B$4="All",COUNTIFS(Task_Tracker!$F$5:$F$1004,$I21,Task_Tracker!$R$5:$R$1004,"Overdue"),COUNTIFS(Task_Tracker!$F$5:$F$1004,$I21,Task_Tracker!$R$5:$R$1004,"Overdue",Task_Tracker!$S$5:$S$1004,$B$4)))
A22: 2026-11 | B22: =COUNTIFS(Task_Tracker!$S$5:$S$1004,$A22,Task_Tracker!$A$5:$A$1004,"<>") | C22: =COUNTIFS(Task_Tracker!$S$5:$S$1004,$A22,Task_Tracker!$I$5:$I$1004,"Completed") | D22: =SUMIFS(Task_Tracker!$O$5:$O$1004,Task_Tracker!$S$5:$S$1004,$A22) | I22: =Employee_Summary!B12 | J22: =IF($I22="","",IF($B$4="All",COUNTIF(Task_Tracker!$F$5:$F$1004,$I22),COUNTIFS(Task_Tracker!$F$5:$F$1004,$I22,Task_Tracker!$S$5:$S$1004,$B$4))) | K22: =IF($I22="","",IF($B$4="All",SUMIF(Task_Tracker!$F$5:$F$1004,$I22,Task_Tracker!$O$5:$O$1004),SUMIFS(Task_Tracker!$O$5:$O$1004,Task_Tracker!$F$5:$F$1004,$I22,Task_Tracker!$S$5:$S$1004,$B$4))) | L22: =IF($I22="","",IF($B$4="All",COUNTIFS(Task_Tracker!$F$5:$F$1004,$I22,Task_Tracker!$R$5:$R$1004,"Overdue"),COUNTIFS(Task_Tracker!$F$5:$F$1004,$I22,Task_Tracker!$R$5:$R$1004,"Overdue",Task_Tracker!$S$5:$S$1004,$B$4)))
A23: 2026-12 | B23: =COUNTIFS(Task_Tracker!$S$5:$S$1004,$A23,Task_Tracker!$A$5:$A$1004,"<>") | C23: =COUNTIFS(Task_Tracker!$S$5:$S$1004,$A23,Task_Tracker!$I$5:$I$1004,"Completed") | D23: =SUMIFS(Task_Tracker!$O$5:$O$1004,Task_Tracker!$S$5:$S$1004,$A23) | I23: =Employee_Summary!B13 | J23: =IF($I23="","",IF($B$4="All",COUNTIF(Task_Tracker!$F$5:$F$1004,$I23),COUNTIFS(Task_Tracker!$F$5:$F$1004,$I23,Task_Tracker!$S$5:$S$1004,$B$4))) | K23: =IF($I23="","",IF($B$4="All",SUMIF(Task_Tracker!$F$5:$F$1004,$I23,Task_Tracker!$O$5:$O$1004),SUMIFS(Task_Tracker!$O$5:$O$1004,Task_Tracker!$F$5:$F$1004,$I23,Task_Tracker!$S$5:$S$1004,$B$4))) | L23: =IF($I23="","",IF($B$4="All",COUNTIFS(Task_Tracker!$F$5:$F$1004,$I23,Task_Tracker!$R$5:$R$1004,"Overdue"),COUNTIFS(Task_Tracker!$F$5:$F$1004,$I23,Task_Tracker!$R$5:$R$1004,"Overdue",Task_Tracker!$S$5:$S$1004,$B$4)))
A24: 2027-01 | B24: =COUNTIFS(Task_Tracker!$S$5:$S$1004,$A24,Task_Tracker!$A$5:$A$1004,"<>") | C24: =COUNTIFS(Task_Tracker!$S$5:$S$1004,$A24,Task_Tracker!$I$5:$I$1004,"Completed") | D24: =SUMIFS(Task_Tracker!$O$5:$O$1004,Task_Tracker!$S$5:$S$1004,$A24) | I24: =Employee_Summary!B14 | J24: =IF($I24="","",IF($B$4="All",COUNTIF(Task_Tracker!$F$5:$F$1004,$I24),COUNTIFS(Task_Tracker!$F$5:$F$1004,$I24,Task_Tracker!$S$5:$S$1004,$B$4))) | K24: =IF($I24="","",IF($B$4="All",SUMIF(Task_Tracker!$F$5:$F$1004,$I24,Task_Tracker!$O$5:$O$1004),SUMIFS(Task_Tracker!$O$5:$O$1004,Task_Tracker!$F$5:$F$1004,$I24,Task_Tracker!$S$5:$S$1004,$B$4))) | L24: =IF($I24="","",IF($B$4="All",COUNTIFS(Task_Tracker!$F$5:$F$1004,$I24,Task_Tracker!$R$5:$R$1004,"Overdue"),COUNTIFS(Task_Tracker!$F$5:$F$1004,$I24,Task_Tracker!$R$5:$R$1004,"Overdue",Task_Tracker!$S$5:$S$1004,$B$4)))
A25: 2027-02 | B25: =COUNTIFS(Task_Tracker!$S$5:$S$1004,$A25,Task_Tracker!$A$5:$A$1004,"<>") | C25: =COUNTIFS(Task_Tracker!$S$5:$S$1004,$A25,Task_Tracker!$I$5:$I$1004,"Completed") | D25: =SUMIFS(Task_Tracker!$O$5:$O$1004,Task_Tracker!$S$5:$S$1004,$A25)
A26: 2027-03 | B26: =COUNTIFS(Task_Tracker!$S$5:$S$1004,$A26,Task_Tracker!$A$5:$A$1004,"<>") | C26: =COUNTIFS(Task_Tracker!$S$5:$S$1004,$A26,Task_Tracker!$I$5:$I$1004,"Completed") | D26: =SUMIFS(Task_Tracker!$O$5:$O$1004,Task_Tracker!$S$5:$S$1004,$A26)
I27: See Employee_Summary for the full employee list and more detailed metrics.

Sheet Monthly_Report_Summary
A1: Monthly Reporting Summary
A2: This sheet gives month-wise totals for all tasks and both employees. Enter or edit tasks in Task_Tracker; reports update automatically.
A4: Month Start | B4: Month | C4: Total Due | D4: Completed | E4: Carry Forward | F4: Actual Hrs | G4: =Employee_Master!$B$5&" Due" | H4: =Employee_Master!$B$5&" Completed" | I4: =Employee_Master!$B$5&" Hrs" | J4: =Employee_Master!$B$6&" Due" | K4: =Employee_Master!$B$6&" Completed" | L4: =Employee_Master!$B$6&" Hrs" | M4: Open in Bucket
A5: 46113 | B5: =TEXT(A5,"mmm yyyy") | C5: =COUNTIFS(Task_Tracker!$L$5:$L$1004,">="&$A5,Task_Tracker!$L$5:$L$1004,"<"&EDATE($A5,1),Task_Tracker!$A$5:$A$1004,"<>") | D5: =COUNTIFS(Task_Tracker!$L$5:$L$1004,">="&$A5,Task_Tracker!$L$5:$L$1004,"<"&EDATE($A5,1),Task_Tracker!$I$5:$I$1004,"Completed") | E5: =COUNTIFS(Task_Tracker!$L$5:$L$1004,"<"&$A5,Task_Tracker!$I$5:$I$1004,"<>Completed",Task_Tracker!$I$5:$I$1004,"<>Cancelled",Task_Tracker!$A$5:$A$1004,"<>") | F5: =SUMIFS(Task_Tracker!$O$5:$O$1004,Task_Tracker!$L$5:$L$1004,">="&$A5,Task_Tracker!$L$5:$L$1004,"<"&EDATE($A5,1)) | G5: =COUNTIFS(Task_Tracker!$F$5:$F$1004,Employee_Master!$B$5,Task_Tracker!$L$5:$L$1004,">="&$A5,Task_Tracker!$L$5:$L$1004,"<"&EDATE($A5,1)) | H5: =COUNTIFS(Task_Tracker!$F$5:$F$1004,Employee_Master!$B$5,Task_Tracker!$L$5:$L$1004,">="&$A5,Task_Tracker!$L$5:$L$1004,"<"&EDATE($A5,1),Task_Tracker!$I$5:$I$1004,"Completed") | I5: =SUMIFS(Task_Tracker!$O$5:$O$1004,Task_Tracker!$F$5:$F$1004,Employee_Master!$B$5,Task_Tracker!$L$5:$L$1004,">="&$A5,Task_Tracker!$L$5:$L$1004,"<"&EDATE($A5,1)) | J5: =COUNTIFS(Task_Tracker!$F$5:$F$1004,Employee_Master!$B$6,Task_Tracker!$L$5:$L$1004,">="&$A5,Task_Tracker!$L$5:$L$1004,"<"&EDATE($A5,1)) | K5: =COUNTIFS(Task_Tracker!$F$5:$F$1004,Employee_Master!$B$6,Task_Tracker!$L$5:$L$1004,">="&$A5,Task_Tracker!$L$5:$L$1004,"<"&EDATE($A5,1),Task_Tracker!$I$5:$I$1004,"Completed") | L5: =SUMIFS(Task_Tracker!$O$5:$O$1004,Task_Tracker!$F$5:$F$1004,Employee_Master!$B$6,Task_Tracker!$L$5:$L$1004,">="&$A5,Task_Tracker!$L$5:$L$1004,"<"&EDATE($A5,1)) | M5: =COUNTIFS(Task_Tracker!$L$5:$L$1004,">="&$A5,Task_Tracker!$L$5:$L$1004,"<"&EDATE($A5,1),Task_Tracker!$I$5:$I$1004,"<>Completed",Task_Tracker!$I$5:$I$1004,"<>Cancelled")
A6: 46143 | B6: =TEXT(A6,"mmm yyyy") | C6: =COUNTIFS(Task_Tracker!$L$5:$L$1004,">="&$A6,Task_Tracker!$L$5:$L$1004,"<"&EDATE($A6,1),Task_Tracker!$A$5:$A$1004,"<>") | D6: =COUNTIFS(Task_Tracker!$L$5:$L$1004,">="&$A6,Task_Tracker!$L$5:$L$1004,"<"&EDATE($A6,1),Task_Tracker!$I$5:$I$1004,"Completed") | E6: =COUNTIFS(Task_Tracker!$L$5:$L$1004,"<"&$A6,Task_Tracker!$I$5:$I$1004,"<>Completed",Task_Tracker!$I$5:$I$1004,"<>Cancelled",Task_Tracker!$A$5:$A$1004,"<>") | F6: =SUMIFS(Task_Tracker!$O$5:$O$1004,Task_Tracker!$L$5:$L$1004,">="&$A6,Task_Tracker!$L$5:$L$1004,"<"&EDATE($A6,1)) | G6: =COUNTIFS(Task_Tracker!$F$5:$F$1004,Employee_Master!$B$5,Task_Tracker!$L$5:$L$1004,">="&$A6,Task_Tracker!$L$5:$L$1004,"<"&EDATE($A6,1)) | H6: =COUNTIFS(Task_Tracker!$F$5:$F$1004,Employee_Master!$B$5,Task_Tracker!$L$5:$L$1004,">="&$A6,Task_Tracker!$L$5:$L$1004,"<"&EDATE($A6,1),Task_Tracker!$I$5:$I$1004,"Completed") | I6: =SUMIFS(Task_Tracker!$O$5:$O$1004,Task_Tracker!$F$5:$F$1004,Employee_Master!$B$5,Task_Tracker!$L$5:$L$1004,">="&$A6,Task_Tracker!$L$5:$L$1004,"<"&EDATE($A6,1)) | J6: =COUNTIFS(Task_Tracker!$F$5:$F$1004,Employee_Master!$B$6,Task_Tracker!$L$5:$L$1004,">="&$A6,Task_Tracker!$L$5:$L$1004,"<"&EDATE($A6,1)) | K6: =COUNTIFS(Task_Tracker!$F$5:$F$1004,Employee_Master!$B$6,Task_Tracker!$L$5:$L$1004,">="&$A6,Task_Tracker!$L$5:$L$1004,"<"&EDATE($A6,1),Task_Tracker!$I$5:$I$1004,"Completed") | L6: =SUMIFS(Task_Tracker!$O$5:$O$1004,Task_Tracker!$F$5:$F$1004,Employee_Master!$B$6,Task_Tracker!$L$5:$L$1004,">="&$A6,Task_Tracker!$L$5:$L$1004,"<"&EDATE($A6,1)) | M6: =COUNTIFS(Task_Tracker!$L$5:$L$1004,">="&$A6,Task_Tracker!$L$5:$L$1004,"<"&EDATE($A6,1),Task_Tracker!$I$5:$I$1004,"<>Completed",Task_Tracker!$I$5:$I$1004,"<>Cancelled")
A7: 46174 | B7: =TEXT(A7,"mmm yyyy") | C7: =COUNTIFS(Task_Tracker!$L$5:$L$1004,">="&$A7,Task_Tracker!$L$5:$L$1004,"<"&EDATE($A7,1),Task_Tracker!$A$5:$A$1004,"<>") | D7: =COUNTIFS(Task_Tracker!$L$5:$L$1004,">="&$A7,Task_Tracker!$L$5:$L$1004,"<"&EDATE($A7,1),Task_Tracker!$I$5:$I$1004,"Completed") | E7: =COUNTIFS(Task_Tracker!$L$5:$L$1004,"<"&$A7,Task_Tracker!$I$5:$I$1004,"<>Completed",Task_Tracker!$I$5:$I$1004,"<>Cancelled",Task_Tracker!$A$5:$A$1004,"<>") | F7: =SUMIFS(Task_Tracker!$O$5:$O$1004,Task_Tracker!$L$5:$L$1004,">="&$A7,Task_Tracker!$L$5:$L$1004,"<"&EDATE($A7,1)) | G7: =COUNTIFS(Task_Tracker!$F$5:$F$1004,Employee_Master!$B$5,Task_Tracker!$L$5:$L$1004,">="&$A7,Task_Tracker!$L$5:$L$1004,"<"&EDATE($A7,1)) | H7: =COUNTIFS(Task_Tracker!$F$5:$F$1004,Employee_Master!$B$5,Task_Tracker!$L$5:$L$1004,">="&$A7,Task_Tracker!$L$5:$L$1004,"<"&EDATE($A7,1),Task_Tracker!$I$5:$I$1004,"Completed") | I7: =SUMIFS(Task_Tracker!$O$5:$O$1004,Task_Tracker!$F$5:$F$1004,Employee_Master!$B$5,Task_Tracker!$L$5:$L$1004,">="&$A7,Task_Tracker!$L$5:$L$1004,"<"&EDATE($A7,1)) | J7: =COUNTIFS(Task_Tracker!$F$5:$F$1004,Employee_Master!$B$6,Task_Tracker!$L$5:$L$1004,">="&$A7,Task_Tracker!$L$5:$L$1004,"<"&EDATE($A7,1)) | K7: =COUNTIFS(Task_Tracker!$F$5:$F$1004,Employee_Master!$B$6,Task_Tracker!$L$5:$L$1004,">="&$A7,Task_Tracker!$L$5:$L$1004,"<"&EDATE($A7,1),Task_Tracker!$I$5:$I$1004,"Completed") | L7: =SUMIFS(Task_Tracker!$O$5:$O$1004,Task_Tracker!$F$5:$F$1004,Employee_Master!$B$6,Task_Tracker!$L$5:$L$1004,">="&$A7,Task_Tracker!$L$5:$L$1004,"<"&EDATE($A7,1)) | M7: =COUNTIFS(Task_Tracker!$L$5:$L$1004,">="&$A7,Task_Tracker!$L$5:$L$1004,"<"&EDATE($A7,1),Task_Tracker!$I$5:$I$1004,"<>Completed",Task_Tracker!$I$5:$I$1004,"<>Cancelled")
A8: 46204 | B8: =TEXT(A8,"mmm yyyy") | C8: =COUNTIFS(Task_Tracker!$L$5:$L$1004,">="&$A8,Task_Tracker!$L$5:$L$1004,"<"&EDATE($A8,1),Task_Tracker!$A$5:$A$1004,"<>") | D8: =COUNTIFS(Task_Tracker!$L$5:$L$1004,">="&$A8,Task_Tracker!$L$5:$L$1004,"<"&EDATE($A8,1),Task_Tracker!$I$5:$I$1004,"Completed") | E8: =COUNTIFS(Task_Tracker!$L$5:$L$1004,"<"&$A8,Task_Tracker!$I$5:$I$1004,"<>Completed",Task_Tracker!$I$5:$I$1004,"<>Cancelled",Task_Tracker!$A$5:$A$1004,"<>") | F8: =SUMIFS(Task_Tracker!$O$5:$O$1004,Task_Tracker!$L$5:$L$1004,">="&$A8,Task_Tracker!$L$5:$L$1004,"<"&EDATE($A8,1)) | G8: =COUNTIFS(Task_Tracker!$F$5:$F$1004,Employee_Master!$B$5,Task_Tracker!$L$5:$L$1004,">="&$A8,Task_Tracker!$L$5:$L$1004,"<"&EDATE($A8,1)) | H8: =COUNTIFS(Task_Tracker!$F$5:$F$1004,Employee_Master!$B$5,Task_Tracker!$L$5:$L$1004,">="&$A8,Task_Tracker!$L$5:$L$1004,"<"&EDATE($A8,1),Task_Tracker!$I$5:$I$1004,"Completed") | I8: =SUMIFS(Task_Tracker!$O$5:$O$1004,Task_Tracker!$F$5:$F$1004,Employee_Master!$B$5,Task_Tracker!$L$5:$L$1004,">="&$A8,Task_Tracker!$L$5:$L$1004,"<"&EDATE($A8,1)) | J8: =COUNTIFS(Task_Tracker!$F$5:$F$1004,Employee_Master!$B$6,Task_Tracker!$L$5:$L$1004,">="&$A8,Task_Tracker!$L$5:$L$1004,"<"&EDATE($A8,1)) | K8: =COUNTIFS(Task_Tracker!$F$5:$F$1004,Employee_Master!$B$6,Task_Tracker!$L$5:$L$1004,">="&$A8,Task_Tracker!$L$5:$L$1004,"<"&EDATE($A8,1),Task_Tracker!$I$5:$I$1004,"Completed") | L8: =SUMIFS(Task_Tracker!$O$5:$O$1004,Task_Tracker!$F$5:$F$1004,Employee_Master!$B$6,Task_Tracker!$L$5:$L$1004,">="&$A8,Task_Tracker!$L$5:$L$1004,"<"&EDATE($A8,1)) | M8: =COUNTIFS(Task_Tracker!$L$5:$L$1004,">="&$A8,Task_Tracker!$L$5:$L$1004,"<"&EDATE($A8,1),Task_Tracker!$I$5:$I$1004,"<>Completed",Task_Tracker!$I$5:$I$1004,"<>Cancelled")
A9: 46235 | B9: =TEXT(A9,"mmm yyyy") | C9: =COUNTIFS(Task_Tracker!$L$5:$L$1004,">="&$A9,Task_Tracker!$L$5:$L$1004,"<"&EDATE($A9,1),Task_Tracker!$A$5:$A$1004,"<>") | D9: =COUNTIFS(Task_Tracker!$L$5:$L$1004,">="&$A9,Task_Tracker!$L$5:$L$1004,"<"&EDATE($A9,1),Task_Tracker!$I$5:$I$1004,"Completed") | E9: =COUNTIFS(Task_Tracker!$L$5:$L$1004,"<"&$A9,Task_Tracker!$I$5:$I$1004,"<>Completed",Task_Tracker!$I$5:$I$1004,"<>Cancelled",Task_Tracker!$A$5:$A$1004,"<>") | F9: =SUMIFS(Task_Tracker!$O$5:$O$1004,Task_Tracker!$L$5:$L$1004,">="&$A9,Task_Tracker!$L$5:$L$1004,"<"&EDATE($A9,1)) | G9: =COUNTIFS(Task_Tracker!$F$5:$F$1004,Employee_Master!$B$5,Task_Tracker!$L$5:$L$1004,">="&$A9,Task_Tracker!$L$5:$L$1004,"<"&EDATE($A9,1)) | H9: =COUNTIFS(Task_Tracker!$F$5:$F$1004,Employee_Master!$B$5,Task_Tracker!$L$5:$L$1004,">="&$A9,Task_Tracker!$L$5:$L$1004,"<"&EDATE($A9,1),Task_Tracker!$I$5:$I$1004,"Completed") | I9: =SUMIFS(Task_Tracker!$O$5:$O$1004,Task_Tracker!$F$5:$F$1004,Employee_Master!$B$5,Task_Tracker!$L$5:$L$1004,">="&$A9,Task_Tracker!$L$5:$L$1004,"<"&EDATE($A9,1)) | J9: =COUNTIFS(Task_Tracker!$F$5:$F$1004,Employee_Master!$B$6,Task_Tracker!$L$5:$L$1004,">="&$A9,Task_Tracker!$L$5:$L$1004,"<"&EDATE($A9,1)) | K9: =COUNTIFS(Task_Tracker!$F$5:$F$1004,Employee_Master!$B$6,Task_Tracker!$L$5:$L$1004,">="&$A9,Task_Tracker!$L$5:$L$1004,"<"&EDATE($A9,1),Task_Tracker!$I$5:$I$1004,"Completed") | L9: =SUMIFS(Task_Tracker!$O$5:$O$1004,Task_Tracker!$F$5:$F$1004,Employee_Master!$B$6,Task_Tracker!$L$5:$L$1004,">="&$A9,Task_Tracker!$L$5:$L$1004,"<"&EDATE($A9,1)) | M9: =COUNTIFS(Task_Tracker!$L$5:$L$1004,">="&$A9,Task_Tracker!$L$5:$L$1004,"<"&EDATE($A9,1),Task_Tracker!$I$5:$I$1004,"<>Completed",Task_Tracker!$I$5:$I$1004,"<>Cancelled")
A10: 46266 | B10: =TEXT(A10,"mmm yyyy") | C10: =COUNTIFS(Task_Tracker!$L$5:$L$1004,">="&$A10,Task_Tracker!$L$5:$L$1004,"<"&EDATE($A10,1),Task_Tracker!$A$5:$A$1004,"<>") | D10: =COUNTIFS(Task_Tracker!$L$5:$L$1004,">="&$A10,Task_Tracker!$L$5:$L$1004,"<"&EDATE($A10,1),Task_Tracker!$I$5:$I$1004,"Completed") | E10: =COUNTIFS(Task_Tracker!$L$5:$L$1004,"<"&$A10,Task_Tracker!$I$5:$I$1004,"<>Completed",Task_Tracker!$I$5:$I$1004,"<>Cancelled",Task_Tracker!$A$5:$A$1004,"<>") | F10: =SUMIFS(Task_Tracker!$O$5:$O$1004,Task_Tracker!$L$5:$L$1004,">="&$A10,Task_Tracker!$L$5:$L$1004,"<"&EDATE($A10,1)) | G10: =COUNTIFS(Task_Tracker!$F$5:$F$1004,Employee_Master!$B$5,Task_Tracker!$L$5:$L$1004,">="&$A10,Task_Tracker!$L$5:$L$1004,"<"&EDATE($A10,1)) | H10: =COUNTIFS(Task_Tracker!$F$5:$F$1004,Employee_Master!$B$5,Task_Tracker!$L$5:$L$1004,">="&$A10,Task_Tracker!$L$5:$L$1004,"<"&EDATE($A10,1),Task_Tracker!$I$5:$I$1004,"Completed") | I10: =SUMIFS(Task_Tracker!$O$5:$O$1004,Task_Tracker!$F$5:$F$1004,Employee_Master!$B$5,Task_Tracker!$L$5:$L$1004,">="&$A10,Task_Tracker!$L$5:$L$1004,"<"&EDATE($A10,1)) | J10: =COUNTIFS(Task_Tracker!$F$5:$F$1004,Employee_Master!$B$6,Task_Tracker!$L$5:$L$1004,">="&$A10,Task_Tracker!$L$5:$L$1004,"<"&EDATE($A10,1)) | K10: =COUNTIFS(Task_Tracker!$F$5:$F$1004,Employee_Master!$B$6,Task_Tracker!$L$5:$L$1004,">="&$A10,Task_Tracker!$L$5:$L$1004,"<"&EDATE($A10,1),Task_Tracker!$I$5:$I$1004,"Completed") | L10: =SUMIFS(Task_Tracker!$O$5:$O$1004,Task_Tracker!$F$5:$F$1004,Employee_Master!$B$6,Task_Tracker!$L$5:$L$1004,">="&$A10,Task_Tracker!$L$5:$L$1004,"<"&EDATE($A10,1)) | M10: =COUNTIFS(Task_Tracker!$L$5:$L$1004,">="&$A10,Task_Tracker!$L$5:$L$1004,"<"&EDATE($A10,1),Task_Tracker!$I$5:$I$1004,"<>Completed",Task_Tracker!$I$5:$I$1004,"<>Cancelled")
A11: 46296 | B11: =TEXT(A11,"mmm yyyy") | C11: =COUNTIFS(Task_Tracker!$L$5:$L$1004,">="&$A11,Task_Tracker!$L$5:$L$1004,"<"&EDATE($A11,1),Task_Tracker!$A$5:$A$1004,"<>") | D11: =COUNTIFS(Task_Tracker!$L$5:$L$1004,">="&$A11,Task_Tracker!$L$5:$L$1004,"<"&EDATE($A11,1),Task_Tracker!$I$5:$I$1004,"Completed") | E11: =COUNTIFS(Task_Tracker!$L$5:$L$1004,"<"&$A11,Task_Tracker!$I$5:$I$1004,"<>Completed",Task_Tracker!$I$5:$I$1004,"<>Cancelled",Task_Tracker!$A$5:$A$1004,"<>") | F11: =SUMIFS(Task_Tracker!$O$5:$O$1004,Task_Tracker!$L$5:$L$1004,">="&$A11,Task_Tracker!$L$5:$L$1004,"<"&EDATE($A11,1)) | G11: =COUNTIFS(Task_Tracker!$F$5:$F$1004,Employee_Master!$B$5,Task_Tracker!$L$5:$L$1004,">="&$A11,Task_Tracker!$L$5:$L$1004,"<"&EDATE($A11,1)) | H11: =COUNTIFS(Task_Tracker!$F$5:$F$1004,Employee_Master!$B$5,Task_Tracker!$L$5:$L$1004,">="&$A11,Task_Tracker!$L$5:$L$1004,"<"&EDATE($A11,1),Task_Tracker!$I$5:$I$1004,"Completed") | I11: =SUMIFS(Task_Tracker!$O$5:$O$1004,Task_Tracker!$F$5:$F$1004,Employee_Master!$B$5,Task_Tracker!$L$5:$L$1004,">="&$A11,Task_Tracker!$L$5:$L$1004,"<"&EDATE($A11,1)) | J11: =COUNTIFS(Task_Tracker!$F$5:$F$1004,Employee_Master!$B$6,Task_Tracker!$L$5:$L$1004,">="&$A11,Task_Tracker!$L$5:$L$1004,"<"&EDATE($A11,1)) | K11: =COUNTIFS(Task_Tracker!$F$5:$F$1004,Employee_Master!$B$6,Task_Tracker!$L$5:$L$1004,">="&$A11,Task_Tracker!$L$5:$L$1004,"<"&EDATE($A11,1),Task_Tracker!$I$5:$I$1004,"Completed") | L11: =SUMIFS(Task_Tracker!$O$5:$O$1004,Task_Tracker!$F$5:$F$1004,Employee_Master!$B$6,Task_Tracker!$L$5:$L$1004,">="&$A11,Task_Tracker!$L$5:$L$1004,"<"&EDATE($A11,1)) | M11: =COUNTIFS(Task_Tracker!$L$5:$L$1004,">="&$A11,Task_Tracker!$L$5:$L$1004,"<"&EDATE($A11,1),Task_Tracker!$I$5:$I$1004,"<>Completed",Task_Tracker!$I$5:$I$1004,"<>Cancelled")
A12: 46327 | B12: =TEXT(A12,"mmm yyyy") | C12: =COUNTIFS(Task_Tracker!$L$5:$L$1004,">="&$A12,Task_Tracker!$L$5:$L$1004,"<"&EDATE($A12,1),Task_Tracker!$A$5:$A$1004,"<>") | D12: =COUNTIFS(Task_Tracker!$L$5:$L$1004,">="&$A12,Task_Tracker!$L$5:$L$1004,"<"&EDATE($A12,1),Task_Tracker!$I$5:$I$1004,"Completed") | E12: =COUNTIFS(Task_Tracker!$L$5:$L$1004,"<"&$A12,Task_Tracker!$I$5:$I$1004,"<>Completed",Task_Tracker!$I$5:$I$1004,"<>Cancelled",Task_Tracker!$A$5:$A$1004,"<>") | F12: =SUMIFS(Task_Tracker!$O$5:$O$1004,Task_Tracker!$L$5:$L$1004,">="&$A12,Task_Tracker!$L$5:$L$1004,"<"&EDATE($A12,1)) | G12: =COUNTIFS(Task_Tracker!$F$5:$F$1004,Employee_Master!$B$5,Task_Tracker!$L$5:$L$1004,">="&$A12,Task_Tracker!$L$5:$L$1004,"<"&EDATE($A12,1)) | H12: =COUNTIFS(Task_Tracker!$F$5:$F$1004,Employee_Master!$B$5,Task_Tracker!$L$5:$L$1004,">="&$A12,Task_Tracker!$L$5:$L$1004,"<"&EDATE($A12,1),Task_Tracker!$I$5:$I$1004,"Completed") | I12: =SUMIFS(Task_Tracker!$O$5:$O$1004,Task_Tracker!$F$5:$F$1004,Employee_Master!$B$5,Task_Tracker!$L$5:$L$1004,">="&$A12,Task_Tracker!$L$5:$L$1004,"<"&EDATE($A12,1)) | J12: =COUNTIFS(Task_Tracker!$F$5:$F$1004,Employee_Master!$B$6,Task_Tracker!$L$5:$L$1004,">="&$A12,Task_Tracker!$L$5:$L$1004,"<"&EDATE($A12,1)) | K12: =COUNTIFS(Task_Tracker!$F$5:$F$1004,Employee_Master!$B$6,Task_Tracker!$L$5:$L$1004,">="&$A12,Task_Tracker!$L$5:$L$1004,"<"&EDATE($A12,1),Task_Tracker!$I$5:$I$1004,"Completed") | L12: =SUMIFS(Task_Tracker!$O$5:$O$1004,Task_Tracker!$F$5:$F$1004,Employee_Master!$B$6,Task_Tracker!$L$5:$L$1004,">="&$A12,Task_Tracker!$L$5:$L$1004,"<"&EDATE($A12,1)) | M12: =COUNTIFS(Task_Tracker!$L$5:$L$1004,">="&$A12,Task_Tracker!$L$5:$L$1004,"<"&EDATE($A12,1),Task_Tracker!$I$5:$I$1004,"<>Completed",Task_Tracker!$I$5:$I$1004,"<>Cancelled")
A13: 46357 | B13: =TEXT(A13,"mmm yyyy") | C13: =COUNTIFS(Task_Tracker!$L$5:$L$1004,">="&$A13,Task_Tracker!$L$5:$L$1004,"<"&EDATE($A13,1),Task_Tracker!$A$5:$A$1004,"<>") | D13: =COUNTIFS(Task_Tracker!$L$5:$L$1004,">="&$A13,Task_Tracker!$L$5:$L$1004,"<"&EDATE($A13,1),Task_Tracker!$I$5:$I$1004,"Completed") | E13: =COUNTIFS(Task_Tracker!$L$5:$L$1004,"<"&$A13,Task_Tracker!$I$5:$I$1004,"<>Completed",Task_Tracker!$I$5:$I$1004,"<>Cancelled",Task_Tracker!$A$5:$A$1004,"<>") | F13: =SUMIFS(Task_Tracker!$O$5:$O$1004,Task_Tracker!$L$5:$L$1004,">="&$A13,Task_Tracker!$L$5:$L$1004,"<"&EDATE($A13,1)) | G13: =COUNTIFS(Task_Tracker!$F$5:$F$1004,Employee_Master!$B$5,Task_Tracker!$L$5:$L$1004,">="&$A13,Task_Tracker!$L$5:$L$1004,"<"&EDATE($A13,1)) | H13: =COUNTIFS(Task_Tracker!$F$5:$F$1004,Employee_Master!$B$5,Task_Tracker!$L$5:$L$1004,">="&$A13,Task_Tracker!$L$5:$L$1004,"<"&EDATE($A13,1),Task_Tracker!$I$5:$I$1004,"Completed") | I13: =SUMIFS(Task_Tracker!$O$5:$O$1004,Task_Tracker!$F$5:$F$1004,Employee_Master!$B$5,Task_Tracker!$L$5:$L$1004,">="&$A13,Task_Tracker!$L$5:$L$1004,"<"&EDATE($A13,1)) | J13: =COUNTIFS(Task_Tracker!$F$5:$F$1004,Employee_Master!$B$6,Task_Tracker!$L$5:$L$1004,">="&$A13,Task_Tracker!$L$5:$L$1004,"<"&EDATE($A13,1)) | K13: =COUNTIFS(Task_Tracker!$F$5:$F$1004,Employee_Master!$B$6,Task_Tracker!$L$5:$L$1004,">="&$A13,Task_Tracker!$L$5:$L$1004,"<"&EDATE($A13,1),Task_Tracker!$I$5:$I$1004,"Completed") | L13: =SUMIFS(Task_Tracker!$O$5:$O$1004,Task_Tracker!$F$5:$F$1004,Employee_Master!$B$6,Task_Tracker!$L$5:$L$1004,">="&$A13,Task_Tracker!$L$5:$L$1004,"<"&EDATE($A13,1)) | M13: =COUNTIFS(Task_Tracker!$L$5:$L$1004,">="&$A13,Task_Tracker!$L$5:$L$1004,"<"&EDATE($A13,1),Task_Tracker!$I$5:$I$1004,"<>Completed",Task_Tracker!$I$5:$I$1004,"<>Cancelled")
A14: 46388 | B14: =TEXT(A14,"mmm yyyy") | C14: =COUNTIFS(Task_Tracker!$L$5:$L$1004,">="&$A14,Task_Tracker!$L$5:$L$1004,"<"&EDATE($A14,1),Task_Tracker!$A$5:$A$1004,"<>") | D14: =COUNTIFS(Task_Tracker!$L$5:$L$1004,">="&$A14,Task_Tracker!$L$5:$L$1004,"<"&EDATE($A14,1),Task_Tracker!$I$5:$I$1004,"Completed") | E14: =COUNTIFS(Task_Tracker!$L$5:$L$1004,"<"&$A14,Task_Tracker!$I$5:$I$1004,"<>Completed",Task_Tracker!$I$5:$I$1004,"<>Cancelled",Task_Tracker!$A$5:$A$1004,"<>") | F14: =SUMIFS(Task_Tracker!$O$5:$O$1004,Task_Tracker!$L$5:$L$1004,">="&$A14,Task_Tracker!$L$5:$L$1004,"<"&EDATE($A14,1)) | G14: =COUNTIFS(Task_Tracker!$F$5:$F$1004,Employee_Master!$B$5,Task_Tracker!$L$5:$L$1004,">="&$A14,Task_Tracker!$L$5:$L$1004,"<"&EDATE($A14,1)) | H14: =COUNTIFS(Task_Tracker!$F$5:$F$1004,Employee_Master!$B$5,Task_Tracker!$L$5:$L$1004,">="&$A14,Task_Tracker!$L$5:$L$1004,"<"&EDATE($A14,1),Task_Tracker!$I$5:$I$1004,"Completed") | I14: =SUMIFS(Task_Tracker!$O$5:$O$1004,Task_Tracker!$F$5:$F$1004,Employee_Master!$B$5,Task_Tracker!$L$5:$L$1004,">="&$A14,Task_Tracker!$L$5:$L$1004,"<"&EDATE($A14,1)) | J14: =COUNTIFS(Task_Tracker!$F$5:$F$1004,Employee_Master!$B$6,Task_Tracker!$L$5:$L$1004,">="&$A14,Task_Tracker!$L$5:$L$1004,"<"&EDATE($A14,1)) | K14: =COUNTIFS(Task_Tracker!$F$5:$F$1004,Employee_Master!$B$6,Task_Tracker!$L$5:$L$1004,">="&$A14,Task_Tracker!$L$5:$L$1004,"<"&EDATE($A14,1),Task_Tracker!$I$5:$I$1004,"Completed") | L14: =SUMIFS(Task_Tracker!$O$5:$O$1004,Task_Tracker!$F$5:$F$1004,Employee_Master!$B$6,Task_Tracker!$L$5:$L$1004,">="&$A14,Task_Tracker!$L$5:$L$1004,"<"&EDATE($A14,1)) | M14: =COUNTIFS(Task_Tracker!$L$5:$L$1004,">="&$A14,Task_Tracker!$L$5:$L$1004,"<"&EDATE($A14,1),Task_Tracker!$I$5:$I$1004,"<>Completed",Task_Tracker!$I$5:$I$1004,"<>Cancelled")
A15: 46419 | B15: =TEXT(A15,"mmm yyyy") | C15: =COUNTIFS(Task_Tracker!$L$5:$L$1004,">="&$A15,Task_Tracker!$L$5:$L$1004,"<"&EDATE($A15,1),Task_Tracker!$A$5:$A$1004,"<>") | D15: =COUNTIFS(Task_Tracker!$L$5:$L$1004,">="&$A15,Task_Tracker!$L$5:$L$1004,"<"&EDATE($A15,1),Task_Tracker!$I$5:$I$1004,"Completed") | E15: =COUNTIFS(Task_Tracker!$L$5:$L$1004,"<"&$A15,Task_Tracker!$I$5:$I$1004,"<>Completed",Task_Tracker!$I$5:$I$1004,"<>Cancelled",Task_Tracker!$A$5:$A$1004,"<>") | F15: =SUMIFS(Task_Tracker!$O$5:$O$1004,Task_Tracker!$L$5:$L$1004,">="&$A15,Task_Tracker!$L$5:$L$1004,"<"&EDATE($A15,1)) | G15: =COUNTIFS(Task_Tracker!$F$5:$F$1004,Employee_Master!$B$5,Task_Tracker!$L$5:$L$1004,">="&$A15,Task_Tracker!$L$5:$L$1004,"<"&EDATE($A15,1)) | H15: =COUNTIFS(Task_Tracker!$F$5:$F$1004,Employee_Master!$B$5,Task_Tracker!$L$5:$L$1004,">="&$A15,Task_Tracker!$L$5:$L$1004,"<"&EDATE($A15,1),Task_Tracker!$I$5:$I$1004,"Completed") | I15: =SUMIFS(Task_Tracker!$O$5:$O$1004,Task_Tracker!$F$5:$F$1004,Employee_Master!$B$5,Task_Tracker!$L$5:$L$1004,">="&$A15,Task_Tracker!$L$5:$L$1004,"<"&EDATE($A15,1)) | J15: =COUNTIFS(Task_Tracker!$F$5:$F$1004,Employee_Master!$B$6,Task_Tracker!$L$5:$L$1004,">="&$A15,Task_Tracker!$L$5:$L$1004,"<"&EDATE($A15,1)) | K15: =COUNTIFS(Task_Tracker!$F$5:$F$1004,Employee_Master!$B$6,Task_Tracker!$L$5:$L$1004,">="&$A15,Task_Tracker!$L$5:$L$1004,"<"&EDATE($A15,1),Task_Tracker!$I$5:$I$1004,"Completed") | L15: =SUMIFS(Task_Tracker!$O$5:$O$1004,Task_Tracker!$F$5:$F$1004,Employee_Master!$B$6,Task_Tracker!$L$5:$L$1004,">="&$A15,Task_Tracker!$L$5:$L$1004,"<"&EDATE($A15,1)) | M15: =COUNTIFS(Task_Tracker!$L$5:$L$1004,">="&$A15,Task_Tracker!$L$5:$L$1004,"<"&EDATE($A15,1),Task_Tracker!$I$5:$I$1004,"<>Completed",Task_Tracker!$I$5:$I$1004,"<>Cancelled")
A16: 46447 | B16: =TEXT(A16,"mmm yyyy") | C16: =COUNTIFS(Task_Tracker!$L$5:$L$1004,">="&$A16,Task_Tracker!$L$5:$L$1004,"<"&EDATE($A16,1),Task_Tracker!$A$5:$A$1004,"<>") | D16: =COUNTIFS(Task_Tracker!$L$5:$L$1004,">="&$A16,Task_Tracker!$L$5:$L$1004,"<"&EDATE($A16,1),Task_Tracker!$I$5:$I$1004,"Completed") | E16: =COUNTIFS(Task_Tracker!$L$5:$L$1004,"<"&$A16,Task_Tracker!$I$5:$I$1004,"<>Completed",Task_Tracker!$I$5:$I$1004,"<>Cancelled",Task_Tracker!$A$5:$A$1004,"<>") | F16: =SUMIFS(Task_Tracker!$O$5:$O$1004,Task_Tracker!$L$5:$L$1004,">="&$A16,Task_Tracker!$L$5:$L$1004,"<"&EDATE($A16,1)) | G16: =COUNTIFS(Task_Tracker!$F$5:$F$1004,Employee_Master!$B$5,Task_Tracker!$L$5:$L$1004,">="&$A16,Task_Tracker!$L$5:$L$1004,"<"&EDATE($A16,1)) | H16: =COUNTIFS(Task_Tracker!$F$5:$F$1004,Employee_Master!$B$5,Task_Tracker!$L$5:$L$1004,">="&$A16,Task_Tracker!$L$5:$L$1004,"<"&EDATE($A16,1),Task_Tracker!$I$5:$I$1004,"Completed") | I16: =SUMIFS(Task_Tracker!$O$5:$O$1004,Task_Tracker!$F$5:$F$1004,Employee_Master!$B$5,Task_Tracker!$L$5:$L$1004,">="&$A16,Task_Tracker!$L$5:$L$1004,"<"&EDATE($A16,1)) | J16: =COUNTIFS(Task_Tracker!$F$5:$F$1004,Employee_Master!$B$6,Task_Tracker!$L$5:$L$1004,">="&$A16,Task_Tracker!$L$5:$L$1004,"<"&EDATE($A16,1)) | K16: =COUNTIFS(Task_Tracker!$F$5:$F$1004,Employee_Master!$B$6,Task_Tracker!$L$5:$L$1004,">="&$A16,Task_Tracker!$L$5:$L$1004,"<"&EDATE($A16,1),Task_Tracker!$I$5:$I$1004,"Completed") | L16: =SUMIFS(Task_Tracker!$O$5:$O$1004,Task_Tracker!$F$5:$F$1004,Employee_Master!$B$6,Task_Tracker!$L$5:$L$1004,">="&$A16,Task_Tracker!$L$5:$L$1004,"<"&EDATE($A16,1)) | M16: =COUNTIFS(Task_Tracker!$L$5:$L$1004,">="&$A16,Task_Tracker!$L$5:$L$1004,"<"&EDATE($A16,1),Task_Tracker!$I$5:$I$1004,"<>Completed",Task_Tracker!$I$5:$I$1004,"<>Cancelled")
A19: Use the monthly tabs for task-by-task detail and carry-forward lines.

Sheet Employee_Master
A1: Employee Master
A2: Add each employee once. Task assignments and reports use this sheet as the source list.
A4: Emp ID | B4: Employee Name | C4: Department | D4: Role | E4: Manager | F4: Email | G4: Join Date | H4: Weekly Capacity (hrs) | I4: Status | J4: Location | K4: Notes
A5: =IF(B5="","","EMP-"&TEXT(ROW()-4,"000")) | B5: Pammi Gaur | C5: Operations | D5: Project Coordinator | E5: Sara Khan | F5: pammi.gaur@company.com | G5: 45853 | H5: 40 | I5: Active | J5: Remote | K5: Owns operations execution, follow-ups, and client coordination.
A6: =IF(B6="","","EMP-"&TEXT(ROW()-4,"000")) | B6: Pankaj Vairagade | C6: Business Systems | D6: Business Analyst | E6: Sara Khan | F6: pankaj.vairagade@company.com | G6: 45600 | H6: 40 | I6: Active | J6: Bengaluru | K6: Handles reporting, audit prep, and process improvement work.
A7: =IF(B7="","","EMP-"&TEXT(ROW()-4,"000"))
A8: =IF(B8="","","EMP-"&TEXT(ROW()-4,"000"))
A9: =IF(B9="","","EMP-"&TEXT(ROW()-4,"000"))
A10: =IF(B10="","","EMP-"&TEXT(ROW()-4,"000"))
A11: =IF(B11="","","EMP-"&TEXT(ROW()-4,"000"))
A12: =IF(B12="","","EMP-"&TEXT(ROW()-4,"000"))
A13: =IF(B13="","","EMP-"&TEXT(ROW()-4,"000"))
A14: =IF(B14="","","EMP-"&TEXT(ROW()-4,"000"))
A15: =IF(B15="","","EMP-"&TEXT(ROW()-4,"000"))
A16: =IF(B16="","","EMP-"&TEXT(ROW()-4,"000"))
A17: =IF(B17="","","EMP-"&TEXT(ROW()-4,"000"))
A18: =IF(B18="","","EMP-"&TEXT(ROW()-4,"000"))
... A204: =IF(B204="","","EMP-"&TEXT(ROW()-4,"000"))

Sheet Task_Tracker
A1: Monthly Task Upload & Master Tracker
A2: Enter or edit all tasks here. Due Date drives the month-wise reporting tabs. Source, manager report status, and linked step IDs update automatically.
A4: Task ID | B4: Project | C4: Program | D4: Task Title | E4: Task Description | F4: Assigned To | G4: Department | H4: Priority | I4: Status | J4: Action Type | K4: Planned Start | L4: Due Date | M4: Completed Date | N4: Est. Hours | O4: Actual Hours | P4: Hours Variance | Q4: Days Open | R4: Overdue Flag | S4: Month Bucket | T4: Progress % | U4: Next Step | V4: Created Date | W4: On-Time Close | X4: Step Count | Y4: Step Completion % | Z4: Task Notes | AA4: Source | AB4: Manager | AC4: Manager Report | AD4: Linked Step IDs | AE4: Open Step Count | AF4: Project Key
A5: =IF(COUNTA(B5:F5)=0,"","TSK-"&TEXT(ROW()-4,"0000")) | B5: Customer Onboarding Revamp | C5: Implementation | D5: Collect client requirements | E5: Gather and confirm onboarding requirements with the client and internal operations team. | F5: Pammi Gaur | G5: =IF($F5="","",IFERROR(INDEX(Employee_Master!$C$5:$C$204,MATCH($F5,Employee_Master!$B$5:$B$204,0)),"")) | H5: High | I5: Completed | J5: =IF($I5="","",IFERROR(INDEX(Action_Status_Map!$B$5:$B$11,MATCH($I5,Action_Status_Map!$A$5:$A$11,0)),"")) | K5: 46113 | L5: 46117 | M5: 46116 | N5: 12 | O5: 11 | P5: =IF(OR($N5="",$O5=""),"",$O5-$N5) | Q5: =IF($K5="","",IF($M5<>"",$M5-$K5,TODAY()-$K5)) | R5: =IF(OR($L5="",$I5="Completed",$I5="Cancelled"),"",IF(AND($L5<TODAY(),$I5<>"Completed",$I5<>"Cancelled"),"Overdue","On Track")) | S5: =IF($L5="","",TEXT($L5,"yyyy-mm")) | T5: =IF($I5="","",IFERROR(INDEX(Action_Status_Map!$C$5:$C$11,MATCH($I5,Action_Status_Map!$A$5:$A$11,0)),"")) | U5: Archive signed scope and handoff to execution. | V5: 46112 | W5: =IF(OR($I5<>"Completed",$M5="",$L5=""),"",IF($M5<=$L5,"Yes","No")) | X5: =IF($A5="","",COUNTIF(Task_Steps!$B$5:$B$2004,$A5)) | Y5: =IF($X5=0,"",COUNTIFS(Task_Steps!$B$5:$B$2004,$A5,Task_Steps!$H$5:$H$2004,"Completed")/$X5) | Z5: Closed one day before deadline. | AA5: Client Request | AB5: =IF($F5="","",IFERROR(INDEX(Employee_Master!$E$5:$E$204,MATCH($F5,Employee_Master!$B$5:$B$204,0)),"")) | AC5: =IF(OR($A5="",$AB5=""),"",IF(OR($I5="Completed",$I5="Cancelled"),"Closed - in Manager Report","Active - in Manager Report")) | AD5: =IF($A5="","",IFERROR(TEXTJOIN(", ",TRUE,FILTER(Task_Steps!$A$5:$A$2004,Task_Steps!$B$5:$B$2004=$A5)),"")) | AE5: =IF($A5="","",COUNTIFS(Task_Steps!$B$5:$B$2004,$A5,Task_Steps!$H$5:$H$2004,"<>Completed",Task_Steps!$H$5:$H$2004,"<>Cancelled")) | AF5: =IF(OR($B5="",$A5=""),"",$B5&" | "&$A5)
A6: =IF(COUNTA(B6:F6)=0,"","TSK-"&TEXT(ROW()-4,"0000")) | B6: Customer Onboarding Revamp | C6: Implementation | D6: Build onboarding checklist | E6: Create the master checklist used for onboarding execution and internal QA. | F6: Pammi Gaur | G6: =IF($F6="","",IFERROR(INDEX(Employee_Master!$C$5:$C$204,MATCH($F6,Employee_Master!$B$5:$B$204,0)),"")) | H6: High | I6: In Progress | J6: =IF($I6="","",IFERROR(INDEX(Action_Status_Map!$B$5:$B$11,MATCH($I6,Action_Status_Map!$A$5:$A$11,0)),"")) | K6: 46118 | L6: 46124 | N6: 10 | O6: 6 | P6: =IF(OR($N6="",$O6=""),"",$O6-$N6) | Q6: =IF($K6="","",IF($M6<>"",$M6-$K6,TODAY()-$K6)) | R6: =IF(OR($L6="",$I6="Completed",$I6="Cancelled"),"",IF(AND($L6<TODAY(),$I6<>"Completed",$I6<>"Cancelled"),"Overdue","On Track")) | S6: =IF($L6="","",TEXT($L6,"yyyy-mm")) | T6: =IF($I6="","",IFERROR(INDEX(Action_Status_Map!$C$5:$C$11,MATCH($I6,Action_Status_Map!$A$5:$A$11,0)),"")) | U6: Finalize version 2 after operations review. | V6: 46117 | W6: =IF(OR($I6<>"Completed",$M6="",$L6=""),"",IF($M6<=$L6,"Yes","No")) | X6: =IF($A6="","",COUNTIF(Task_Steps!$B$5:$B$2004,$A6)) | Y6: =IF($X6=0,"",COUNTIFS(Task_Steps!$B$5:$B$2004,$A6,Task_Steps!$H$5:$H$2004,"Completed")/$X6) | Z6: Core delivery task for current week. | AA6: Operations Review | AB6: =IF($F6="","",IFERROR(INDEX(Employee_Master!$E$5:$E$204,MATCH($F6,Employee_Master!$B$5:$B$204,0)),"")) | AC6: =IF(OR($A6="",$AB6=""),"",IF(OR($I6="Completed",$I6="Cancelled"),"Closed - in Manager Report","Active - in Manager Report")) | AD6: =IF($A6="","",IFERROR(TEXTJOIN(", ",TRUE,FILTER(Task_Steps!$A$5:$A$2004,Task_Steps!$B$5:$B$2004=$A6)),"")) | AE6: =IF($A6="","",COUNTIFS(Task_Steps!$B$5:$B$2004,$A6,Task_Steps!$H$5:$H$2004,"<>Completed",Task_Steps!$H$5:$H$2004,"<>Cancelled")) | AF6: =IF(OR($B6="",$A6=""),"",$B6&" | "&$A6)
A7: =IF(COUNTA(B7:F7)=0,"","TSK-"&TEXT(ROW()-4,"0000")) | B7: Customer Onboarding Revamp | C7: Training | D7: Schedule client training sessions | E7: Coordinate training slots, attendees, and agenda for rollout. | F7: Pammi Gaur | G7: =IF($F7="","",IFERROR(INDEX(Employee_Master!$C$5:$C$204,MATCH($F7,Employee_Master!$B$5:$B$204,0)),"")) | H7: Medium | I7: Review | J7: =IF($I7="","",IFERROR(INDEX(Action_Status_Map!$B$5:$B$11,MATCH($I7,Action_Status_Map!$A$5:$A$11,0)),"")) | K7: 46120 | L7: 46126 | N7: 8 | O7: 7 | P7: =IF(OR($N7="",$O7=""),"",$O7-$N7) | Q7: =IF($K7="","",IF($M7<>"",$M7-$K7,TODAY()-$K7)) | R7: =IF(OR($L7="",$I7="Completed",$I7="Cancelled"),"",IF(AND($L7<TODAY(),$I7<>"Completed",$I7<>"Cancelled"),"Overdue","On Track")) | S7: =IF($L7="","",TEXT($L7,"yyyy-mm")) | T7: =IF($I7="","",IFERROR(INDEX(Action_Status_Map!$C$5:$C$11,MATCH($I7,Action_Status_Map!$A$5:$A$11,0)),"")) | U7: Await leadership approval for final schedule. | V7: 46119 | W7: =IF(OR($I7<>"Completed",$M7="",$L7=""),"",IF($M7<=$L7,"Yes","No")) | X7: =IF($A7="","",COUNTIF(Task_Steps!$B$5:$B$2004,$A7)) | Y7: =IF($X7=0,"",COUNTIFS(Task_Steps!$B$5:$B$2004,$A7,Task_Steps!$H$5:$H$2004,"Completed")/$X7) | Z7: Content ready; waiting on confirmation. | AA7: Leadership Follow-up | AB7: =IF($F7="","",IFERROR(INDEX(Employee_Master!$E$5:$E$204,MATCH($F7,Employee_Master!$B$5:$B$204,0)),"")) | AC7: =IF(OR($A7="",$AB7=""),"",IF(OR($I7="Completed",$I7="Cancelled"),"Closed - in Manager Report","Active - in Manager Report")) | AD7: =IF($A7="","",IFERROR(TEXTJOIN(", ",TRUE,FILTER(Task_Steps!$A$5:$A$2004,Task_Steps!$B$5:$B$2004=$A7)),"")) | AE7: =IF($A7="","",COUNTIFS(Task_Steps!$B$5:$B$2004,$A7,Task_Steps!$H$5:$H$2004,"<>Completed",Task_Steps!$H$5:$H$2004,"<>Cancelled")) | AF7: =IF(OR($B7="",$A7=""),"",$B7&" | "&$A7)
A8: =IF(COUNTA(B8:F8)=0,"","TSK-"&TEXT(ROW()-4,"0000")) | B8: Website Migration | C8: Operations | D8: Vendor coordination for content freeze | E8: Lock the final website content set and confirm the vendor freeze date. | F8: Pammi Gaur | G8: =IF($F8="","",IFERROR(INDEX(Employee_Master!$C$5:$C$204,MATCH($F8,Employee_Master!$B$5:$B$204,0)),"")) | H8: Critical | I8: Blocked | J8: =IF($I8="","",IFERROR(INDEX(Action_Status_Map!$B$5:$B$11,MATCH($I8,Action_Status_Map!$A$5:$A$11,0)),"")) | K8: 46115 | L8: 46120 | N8: 6 | O8: 3 | P8: =IF(OR($N8="",$O8=""),"",$O8-$N8) | Q8: =IF($K8="","",IF($M8<>"",$M8-$K8,TODAY()-$K8)) | R8: =IF(OR($L8="",$I8="Completed",$I8="Cancelled"),"",IF(AND($L8<TODAY(),$I8<>"Completed",$I8<>"Cancelled"),"Overdue","On Track")) | S8: =IF($L8="","",TEXT($L8,"yyyy-mm")) | T8: =IF($I8="","",IFERROR(INDEX(Action_Status_Map!$C$5:$C$11,MATCH($I8,Action_Status_Map!$A$5:$A$11,0)),"")) | U8: Need vendor approval to proceed. | V8: 46114 | W8: =IF(OR($I8<>"Completed",$M8="",$L8=""),"",IF($M8<=$L8,"Yes","No")) | X8: =IF($A8="","",COUNTIF(Task_Steps!$B$5:$B$2004,$A8)) | Y8: =IF($X8=0,"",COUNTIFS(Task_Steps!$B$5:$B$2004,$A8,Task_Steps!$H$5:$H$2004,"Completed")/$X8) | Z8: Blocked by external dependency; now overdue. | AA8: Vendor Dependency | AB8: =IF($F8="","",IFERROR(INDEX(Employee_Master!$E$5:$E$204,MATCH($F8,Employee_Master!$B$5:$B$204,0)),"")) | AC8: =IF(OR($A8="",$AB8=""),"",IF(OR($I8="Completed",$I8="Cancelled"),"Closed - in Manager Report","Active - in Manager Report")) | AD8: =IF($A8="","",IFERROR(TEXTJOIN(", ",TRUE,FILTER(Task_Steps!$A$5:$A$2004,Task_Steps!$B$5:$B$2004=$A8)),"")) | AE8: =IF($A8="","",COUNTIFS(Task_Steps!$B$5:$B$2004,$A8,Task_Steps!$H$5:$H$2004,"<>Completed",Task_Steps!$H$5:$H$2004,"<>Cancelled")) | AF8: =IF(OR($B8="",$A8=""),"",$B8&" | "&$A8)
A9: =IF(COUNTA(B9:F9)=0,"","TSK-"&TEXT(ROW()-4,"0000")) | B9: Customer Portal Launch | C9: Go-Live | D9: Prepare launch readiness checklist | E9: Prepare pre-launch readiness checks and stakeholder signoffs. | F9: Pammi Gaur | G9: =IF($F9="","",IFERROR(INDEX(Employee_Master!$C$5:$C$204,MATCH($F9,Employee_Master!$B$5:$B$204,0)),"")) | H9: High | I9: Not Started | J9: =IF($I9="","",IFERROR(INDEX(Action_Status_Map!$B$5:$B$11,MATCH($I9,Action_Status_Map!$A$5:$A$11,0)),"")) | K9: 46143 | L9: 46150 | N9: 7 | P9: =IF(OR($N9="",$O9=""),"",$O9-$N9) | Q9: =IF($K9="","",IF($M9<>"",$M9-$K9,TODAY()-$K9)) | R9: =IF(OR($L9="",$I9="Completed",$I9="Cancelled"),"",IF(AND($L9<TODAY(),$I9<>"Completed",$I9<>"Cancelled"),"Overdue","On Track")) | S9: =IF($L9="","",TEXT($L9,"yyyy-mm")) | T9: =IF($I9="","",IFERROR(INDEX(Action_Status_Map!$C$5:$C$11,MATCH($I9,Action_Status_Map!$A$5:$A$11,0)),"")) | U9: Kick off launch checklist in May. | V9: 46121 | W9: =IF(OR($I9<>"Completed",$M9="",$L9=""),"",IF($M9<=$L9,"Yes","No")) | X9: =IF($A9="","",COUNTIF(Task_Steps!$B$5:$B$2004,$A9)) | Y9: =IF($X9=0,"",COUNTIFS(Task_Steps!$B$5:$B$2004,$A9,Task_Steps!$H$5:$H$2004,"Completed")/$X9) | Z9: Upcoming task already planned. | AA9: Program Plan | AB9: =IF($F9="","",IFERROR(INDEX(Employee_Master!$E$5:$E$204,MATCH($F9,Employee_Master!$B$5:$B$204,0)),"")) | AC9: =IF(OR($A9="",$AB9=""),"",IF(OR($I9="Completed",$I9="Cancelled"),"Closed - in Manager Report","Active - in Manager Report")) | AD9: =IF($A9="","",IFERROR(TEXTJOIN(", ",TRUE,FILTER(Task_Steps!$A$5:$A$2004,Task_Steps!$B$5:$B$2004=$A9)),"")) | AE9: =IF($A9="","",COUNTIFS(Task_Steps!$B$5:$B$2004,$A9,Task_Steps!$H$5:$H$2004,"<>Completed",Task_Steps!$H$5:$H$2004,"<>Cancelled")) | AF9: =IF(OR($B9="",$A9=""),"",$B9&" | "&$A9)
A10: =IF(COUNTA(B10:F10)=0,"","TSK-"&TEXT(ROW()-4,"0000")) | B10: Website Migration | C10: Analytics | D10: Set up UAT defect log | E10: Create the testing log and owner matrix for website UAT. | F10: Pankaj Vairagade | G10: =IF($F10="","",IFERROR(INDEX(Employee_Master!$C$5:$C$204,MATCH($F10,Employee_Master!$B$5:$B$204,0)),"")) | H10: High | I10: Completed | J10: =IF($I10="","",IFERROR(INDEX(Action_Status_Map!$B$5:$B$11,MATCH($I10,Action_Status_Map!$A$5:$A$11,0)),"")) | K10: 46114 | L10: 46119 | M10: 46119 | N10: 9 | O10: 10 | P10: =IF(OR($N10="",$O10=""),"",$O10-$N10) | Q10: =IF($K10="","",IF($M10<>"",$M10-$K10,TODAY()-$K10)) | R10: =IF(OR($L10="",$I10="Completed",$I10="Cancelled"),"",IF(AND($L10<TODAY(),$I10<>"Completed",$I10<>"Cancelled"),"Overdue","On Track")) | S10: =IF($L10="","",TEXT($L10,"yyyy-mm")) | T10: =IF($I10="","",IFERROR(INDEX(Action_Status_Map!$C$5:$C$11,MATCH($I10,Action_Status_Map!$A$5:$A$11,0)),"")) | U10: Share closure summary with stakeholders. | V10: 46113 | W10: =IF(OR($I10<>"Completed",$M10="",$L10=""),"",IF($M10<=$L10,"Yes","No")) | X10: =IF($A10="","",COUNTIF(Task_Steps!$B$5:$B$2004,$A10)) | Y10: =IF($X10=0,"",COUNTIFS(Task_Steps!$B$5:$B$2004,$A10,Task_Steps!$H$5:$H$2004,"Completed")/$X10) | Z10: Completed on time with slight overrun. | AA10: Audit Request | AB10: =IF($F10="","",IFERROR(INDEX(Employee_Master!$E$5:$E$204,MATCH($F10,Employee_Master!$B$5:$B$204,0)),"")) | AC10: =IF(OR($A10="",$AB10=""),"",IF(OR($I10="Completed",$I10="Cancelled"),"Closed - in Manager Report","Active - in Manager Report")) | AD10: =IF($A10="","",IFERROR(TEXTJOIN(", ",TRUE,FILTER(Task_Steps!$A$5:$A$2004,Task_Steps!$B$5:$B$2004=$A10)),"")) | AE10: =IF($A10="","",COUNTIFS(Task_Steps!$B$5:$B$2004,$A10,Task_Steps!$H$5:$H$2004,"<>Completed",Task_Steps!$H$5:$H$2004,"<>Cancelled")) | AF10: =IF(OR($B10="",$A10=""),"",$B10&" | "&$A10)
A11: =IF(COUNTA(B11:F11)=0,"","TSK-"&TEXT(ROW()-4,"0000")) | B11: Website Migration | C11: Reporting | D11: Create weekly progress dashboard | E11: Build the weekly dashboard showing delivery, defects, and risks. | F11: Pankaj Vairagade | G11: =IF($F11="","",IFERROR(INDEX(Employee_Master!$C$5:$C$204,MATCH($F11,Employee_Master!$B$5:$B$204,0)),"")) | H11: Critical | I11: In Progress | J11: =IF($I11="","",IFERROR(INDEX(Action_Status_Map!$B$5:$B$11,MATCH($I11,Action_Status_Map!$A$5:$A$11,0)),"")) | K11: 46117 | L11: 46127 | N11: 14 | O11: 9 | P11: =IF(OR($N11="",$O11=""),"",$O11-$N11) | Q11: =IF($K11="","",IF($M11<>"",$M11-$K11,TODAY()-$K11)) | R11: =IF(OR($L11="",$I11="Completed",$I11="Cancelled"),"",IF(AND($L11<TODAY(),$I11<>"Completed",$I11<>"Cancelled"),"Overdue","On Track")) | S11: =IF($L11="","",TEXT($L11,"yyyy-mm")) | T11: =IF($I11="","",IFERROR(INDEX(Action_Status_Map!$C$5:$C$11,MATCH($I11,Action_Status_Map!$A$5:$A$11,0)),"")) | U11: Add leadership metrics and QA final formulas. | V11: 46116 | W11: =IF(OR($I11<>"Completed",$M11="",$L11=""),"",IF($M11<=$L11,"Yes","No")) | X11: =IF($A11="","",COUNTIF(Task_Steps!$B$5:$B$2004,$A11)) | Y11: =IF($X11=0,"",COUNTIFS(Task_Steps!$B$5:$B$2004,$A11,Task_Steps!$H$5:$H$2004,"Completed")/$X11) | Z11: High-visibility reporting deliverable. | AA11: Internal Compliance | AB11: =IF($F11="","",IFERROR(INDEX(Employee_Master!$E$5:$E$204,MATCH($F11,Employee_Master!$B$5:$B$204,0)),"")) | AC11: =IF(OR($A11="",$AB11=""),"",IF(OR($I11="Completed",$I11="Cancelled"),"Closed - in Manager Report","Active - in Manager Report")) | AD11: =IF($A11="","",IFERROR(TEXTJOIN(", ",TRUE,FILTER(Task_Steps!$A$5:$A$2004,Task_Steps!$B$5:$B$2004=$A11)),"")) | AE11: =IF($A11="","",COUNTIFS(Task_Steps!$B$5:$B$2004,$A11,Task_Steps!$H$5:$H$2004,"<>Completed",Task_Steps!$H$5:$H$2004,"<>Cancelled")) | AF11: =IF(OR($B11="",$A11=""),"",$B11&" | "&$A11)
A12: =IF(COUNTA(B12:F12)=0,"","TSK-"&TEXT(ROW()-4,"0000")) | B12: Q2 Compliance Audit | C12: Documentation | D12: Compile policy evidence pack | E12: Collect policies, approvals, and evidence files for audit review. | F12: Pankaj Vairagade | G12: =IF($F12="","",IFERROR(INDEX(Employee_Master!$C$5:$C$204,MATCH($F12,Employee_Master!$B$5:$B$204,0)),"")) | H12: Critical | I12: On Hold | J12: =IF($I12="","",IFERROR(INDEX(Action_Status_Map!$B$5:$B$11,MATCH($I12,Action_Status_Map!$A$5:$A$11,0)),"")) | K12: 46116 | L12: 46122 | N12: 16 | O12: 5 | P12: =IF(OR($N12="",$O12=""),"",$O12-$N12) | Q12: =IF($K12="","",IF($M12<>"",$M12-$K12,TODAY()-$K12)) | R12: =IF(OR($L12="",$I12="Completed",$I12="Cancelled"),"",IF(AND($L12<TODAY(),$I12<>"Completed",$I12<>"Cancelled"),"Overdue","On Track")) | S12: =IF($L12="","",TEXT($L12,"yyyy-mm")) | T12: =IF($I12="","",IFERROR(INDEX(Action_Status_Map!$C$5:$C$11,MATCH($I12,Action_Status_Map!$A$5:$A$11,0)),"")) | U12: Waiting for legal documents before pack can be completed. | V12: 46115 | W12: =IF(OR($I12<>"Completed",$M12="",$L12=""),"",IF($M12<=$L12,"Yes","No")) | X12: =IF($A12="","",COUNTIF(Task_Steps!$B$5:$B$2004,$A12)) | Y12: =IF($X12=0,"",COUNTIFS(Task_Steps!$B$5:$B$2004,$A12,Task_Steps!$H$5:$H$2004,"Completed")/$X12) | Z12: Paused pending legal input. | AA12: System Improvement | AB12: =IF($F12="","",IFERROR(INDEX(Employee_Master!$E$5:$E$204,MATCH($F12,Employee_Master!$B$5:$B$204,0)),"")) | AC12: =IF(OR($A12="",$AB12=""),"",IF(OR($I12="Completed",$I12="Cancelled"),"Closed - in Manager Report","Active - in Manager Report")) | AD12: =IF($A12="","",IFERROR(TEXTJOIN(", ",TRUE,FILTER(Task_Steps!$A$5:$A$2004,Task_Steps!$B$5:$B$2004=$A12)),"")) | AE12: =IF($A12="","",COUNTIFS(Task_Steps!$B$5:$B$2004,$A12,Task_Steps!$H$5:$H$2004,"<>Completed",Task_Steps!$H$5:$H$2004,"<>Cancelled")) | AF12: =IF(OR($B12="",$A12=""),"",$B12&" | "&$A12)
A13: =IF(COUNTA(B13:F13)=0,"","TSK-"&TEXT(ROW()-4,"0000")) | B13: Q2 Compliance Audit | C13: Automation | D13: Automate control checklist | E13: Turn the manual compliance checklist into a reusable controlled template. | F13: Pankaj Vairagade | G13: =IF($F13="","",IFERROR(INDEX(Employee_Master!$C$5:$C$204,MATCH($F13,Employee_Master!$B$5:$B$204,0)),"")) | H13: Medium | I13: Not Started | J13: =IF($I13="","",IFERROR(INDEX(Action_Status_Map!$B$5:$B$11,MATCH($I13,Action_Status_Map!$A$5:$A$11,0)),"")) | K13: 46123 | L13: 46134 | N13: 18 | P13: =IF(OR($N13="",$O13=""),"",$O13-$N13) | Q13: =IF($K13="","",IF($M13<>"",$M13-$K13,TODAY()-$K13)) | R13: =IF(OR($L13="",$I13="Completed",$I13="Cancelled"),"",IF(AND($L13<TODAY(),$I13<>"Completed",$I13<>"Cancelled"),"Overdue","On Track")) | S13: =IF($L13="","",TEXT($L13,"yyyy-mm")) | T13: =IF($I13="","",IFERROR(INDEX(Action_Status_Map!$C$5:$C$11,MATCH($I13,Action_Status_Map!$A$5:$A$11,0)),"")) | U13: Kick off automation design with IT. | V13: 46121 | W13: =IF(OR($I13<>"Completed",$M13="",$L13=""),"",IF($M13<=$L13,"Yes","No")) | X13: =IF($A13="","",COUNTIF(Task_Steps!$B$5:$B$2004,$A13)) | Y13: =IF($X13=0,"",COUNTIFS(Task_Steps!$B$5:$B$2004,$A13,Task_Steps!$H$5:$H$2004,"Completed")/$X13) | Z13: Planned for later this month. | AA13: Management Review | AB13: =IF($F13="","",IFERROR(INDEX(Employee_Master!$E$5:$E$204,MATCH($F13,Employee_Master!$B$5:$B$204,0)),"")) | AC13: =IF(OR($A13="",$AB13=""),"",IF(OR($I13="Completed",$I13="Cancelled"),"Closed - in Manager Report","Active - in Manager Report")) | AD13: =IF($A13="","",IFERROR(TEXTJOIN(", ",TRUE,FILTER(Task_Steps!$A$5:$A$2004,Task_Steps!$B$5:$B$2004=$A13)),"")) | AE13: =IF($A13="","",COUNTIFS(Task_Steps!$B$5:$B$2004,$A13,Task_Steps!$H$5:$H$2004,"<>Completed",Task_Steps!$H$5:$H$2004,"<>Cancelled")) | AF13: =IF(OR($B13="",$A13=""),"",$B13&" | "&$A13)
A14: =IF(COUNTA(B14:F14)=0,"","TSK-"&TEXT(ROW()-4,"0000")) | B14: Process Excellence | C14: Reporting | D14: Monthly KPI workbook cleanup | E14: Clean tabs, formulas, and broken links in the KPI workbook. | F14: Pankaj Vairagade | G14: =IF($F14="","",IFERROR(INDEX(Employee_Master!$C$5:$C$204,MATCH($F14,Employee_Master!$B$5:$B$204,0)),"")) | H14: Low | I14: Completed | J14: =IF($I14="","",IFERROR(INDEX(Action_Status_Map!$B$5:$B$11,MATCH($I14,Action_Status_Map!$A$5:$A$11,0)),"")) | K14: 46105 | L14: 46110 | M14: 46109 | N14: 5 | O14: 4 | P14: =IF(OR($N14="",$O14=""),"",$O14-$N14) | Q14: =IF($K14="","",IF($M14<>"",$M14-$K14,TODAY()-$K14)) | R14: =IF(OR($L14="",$I14="Completed",$I14="Cancelled"),"",IF(AND($L14<TODAY(),$I14<>"Completed",$I14<>"Cancelled"),"Overdue","On Track")) | S14: =IF($L14="","",TEXT($L14,"yyyy-mm")) | T14: =IF($I14="","",IFERROR(INDEX(Action_Status_Map!$C$5:$C$11,MATCH($I14,Action_Status_Map!$A$5:$A$11,0)),"")) | U14: Archive previous version and publish final file. | V14: 46104 | W14: =IF(OR($I14<>"Completed",$M14="",$L14=""),"",IF($M14<=$L14,"Yes","No")) | X14: =IF($A14="","",COUNTIF(Task_Steps!$B$5:$B$2004,$A14)) | Y14: =IF($X14=0,"",COUNTIFS(Task_Steps!$B$5:$B$2004,$A14,Task_Steps!$H$5:$H$2004,"Completed")/$X14) | Z14: Closed early with clean handoff. | AA14: Recurring Reporting | AB14: =IF($F14="","",IFERROR(INDEX(Employee_Master!$E$5:$E$204,MATCH($F14,Employee_Master!$B$5:$B$204,0)),"")) | AC14: =IF(OR($A14="",$AB14=""),"",IF(OR($I14="Completed",$I14="Cancelled"),"Closed - in Manager Report","Active - in Manager Report")) | AD14: =IF($A14="","",IFERROR(TEXTJOIN(", ",TRUE,FILTER(Task_Steps!$A$5:$A$2004,Task_Steps!$B$5:$B$2004=$A14)),"")) | AE14: =IF($A14="","",COUNTIFS(Task_Steps!$B$5:$B$2004,$A14,Task_Steps!$H$5:$H$2004,"<>Completed",Task_Steps!$H$5:$H$2004,"<>Cancelled")) | AF14: =IF(OR($B14="",$A14=""),"",$B14&" | "&$A14)
A15: =IF(COUNTA(B15:F15)=0,"","TSK-"&TEXT(ROW()-4,"0000")) | B15: Customer Portal Launch | C15: UAT | D15: Complete UAT signoff pack | E15: Compile test evidence, approvals, and release notes for signoff. | F15: Pammi Gaur | G15: =IF($F15="","",IFERROR(INDEX(Employee_Master!$C$5:$C$204,MATCH($F15,Employee_Master!$B$5:$B$204,0)),"")) | H15: High | I15: Completed | J15: =IF($I15="","",IFERROR(INDEX(Action_Status_Map!$B$5:$B$11,MATCH($I15,Action_Status_Map!$A$5:$A$11,0)),"")) | K15: 46151 | L15: 46162 | M15: 46161 | N15: 8 | O15: 9 | P15: =IF(OR($N15="",$O15=""),"",$O15-$N15) | Q15: =IF($K15="","",IF($M15<>"",$M15-$K15,TODAY()-$K15)) | R15: =IF(OR($L15="",$I15="Completed",$I15="Cancelled"),"",IF(AND($L15<TODAY(),$I15<>"Completed",$I15<>"Cancelled"),"Overdue","On Track")) | S15: =IF($L15="","",TEXT($L15,"yyyy-mm")) | T15: =IF($I15="","",IFERROR(INDEX(Action_Status_Map!$C$5:$C$11,MATCH($I15,Action_Status_Map!$A$5:$A$11,0)),"")) | U15: Share the final signoff pack with the sponsor team. | V15: 46150 | W15: =IF(OR($I15<>"Completed",$M15="",$L15=""),"",IF($M15<=$L15,"Yes","No")) | X15: =IF($A15="","",COUNTIF(Task_Steps!$B$5:$B$2004,$A15)) | Y15: =IF($X15=0,"",COUNTIFS(Task_Steps!$B$5:$B$2004,$A15,Task_Steps!$H$5:$H$2004,"Completed")/$X15) | Z15: Completed one day early with minor extra effort. | AA15: Client Escalation | AB15: =IF($F15="","",IFERROR(INDEX(Employee_Master!$E$5:$E$204,MATCH($F15,Employee_Master!$B$5:$B$204,0)),"")) | AC15: =IF(OR($A15="",$AB15=""),"",IF(OR($I15="Completed",$I15="Cancelled"),"Closed - in Manager Report","Active - in Manager Report")) | AD15: =IF($A15="","",IFERROR(TEXTJOIN(", ",TRUE,FILTER(Task_Steps!$A$5:$A$2004,Task_Steps!$B$5:$B$2004=$A15)),"")) | AE15: =IF($A15="","",COUNTIFS(Task_Steps!$B$5:$B$2004,$A15,Task_Steps!$H$5:$H$2004,"<>Completed",Task_Steps!$H$5:$H$2004,"<>Cancelled")) | AF15: =IF(OR($B15="",$A15=""),"",$B15&" | "&$A15)
A16: =IF(COUNTA(B16:F16)=0,"","TSK-"&TEXT(ROW()-4,"0000")) | B16: Vendor Migration | C16: Planning | D16: Finalize migration cutover checklist | E16: Prepare the final cutover checklist covering owners, timings, and rollback plan. | F16: Pammi Gaur | G16: =IF($F16="","",IFERROR(INDEX(Employee_Master!$C$5:$C$204,MATCH($F16,Employee_Master!$B$5:$B$204,0)),"")) | H16: Critical | I16: In Progress | J16: =IF($I16="","",IFERROR(INDEX(Action_Status_Map!$B$5:$B$11,MATCH($I16,Action_Status_Map!$A$5:$A$11,0)),"")) | K16: 46174 | L16: 46179 | N16: 10 | O16: 4 | P16: =IF(OR($N16="",$O16=""),"",$O16-$N16) | Q16: =IF($K16="","",IF($M16<>"",$M16-$K16,TODAY()-$K16)) | R16: =IF(OR($L16="",$I16="Completed",$I16="Cancelled"),"",IF(AND($L16<TODAY(),$I16<>"Completed",$I16<>"Cancelled"),"Overdue","On Track")) | S16: =IF($L16="","",TEXT($L16,"yyyy-mm")) | T16: =IF($I16="","",IFERROR(INDEX(Action_Status_Map!$C$5:$C$11,MATCH($I16,Action_Status_Map!$A$5:$A$11,0)),"")) | U16: Collect final approvals from infra and vendor teams. | V16: 46171 | W16: =IF(OR($I16<>"Completed",$M16="",$L16=""),"",IF($M16<=$L16,"Yes","No")) | X16: =IF($A16="","",COUNTIF(Task_Steps!$B$5:$B$2004,$A16)) | Y16: =IF($X16=0,"",COUNTIFS(Task_Steps!$B$5:$B$2004,$A16,Task_Steps!$H$5:$H$2004,"Completed")/$X16) | Z16: Key June deliverable now in progress. | AA16: Change Request | AB16: =IF($F16="","",IFERROR(INDEX(Employee_Master!$E$5:$E$204,MATCH($F16,Employee_Master!$B$5:$B$204,0)),"")) | AC16: =IF(OR($A16="",$AB16=""),"",IF(OR($I16="Completed",$I16="Cancelled"),"Closed - in Manager Report","Active - in Manager Report")) | AD16: =IF($A16="","",IFERROR(TEXTJOIN(", ",TRUE,FILTER(Task_Steps!$A$5:$A$2004,Task_Steps!$B$5:$B$2004=$A16)),"")) | AE16: =IF($A16="","",COUNTIFS(Task_Steps!$B$5:$B$2004,$A16,Task_Steps!$H$5:$H$2004,"<>Completed",Task_Steps!$H$5:$H$2004,"<>Cancelled")) | AF16: =IF(OR($B16="",$A16=""),"",$B16&" | "&$A16)
